2025-03-12 11:00:53,688 - app.api.v1.organization_routes - ERROR - Error fetching organization details: greenlet_spawn has not been called; can't call await_only() here. Was IO attempted in an unexpected place? (Background on this error at: https://sqlalche.me/e/20/xd2s)
Traceback (most recent call last):
  File "/home/runner/workspace/app/api/v1/organization_routes.py", line 177, in get_organization_details
    file_responses = [
                     ^
  File "/home/runner/workspace/app/api/v1/organization_routes.py", line 184, in <listcomp>
    chunks_count=len(f.knowledge_base) if hasattr(f, 'knowledge_base') and f.knowledge_base else 0
                                          ^^^^^^^^^^^^^^^^^^^^^^^^^^^^
  File "/home/runner/workspace/.pythonlibs/lib/python3.11/site-packages/sqlalchemy/orm/attributes.py", line 566, in __get__
    return self.impl.get(state, dict_)  # type: ignore[no-any-return]
           ^^^^^^^^^^^^^^^^^^^^^^^^^^^
  File "/home/runner/workspace/.pythonlibs/lib/python3.11/site-packages/sqlalchemy/orm/attributes.py", line 1086, in get
    value = self._fire_loader_callables(state, key, passive)
            ^^^^^^^^^^^^^^^^^^^^^^^^^^^^^^^^^^^^^^^^^^^^^^^^
  File "/home/runner/workspace/.pythonlibs/lib/python3.11/site-packages/sqlalchemy/orm/attributes.py", line 1121, in _fire_loader_callables
    return self.callable_(state, passive)
           ^^^^^^^^^^^^^^^^^^^^^^^^^^^^^^
  File "/home/runner/workspace/.pythonlibs/lib/python3.11/site-packages/sqlalchemy/orm/strategies.py", line 978, in _load_for_state
    return self._emit_lazyload(
           ^^^^^^^^^^^^^^^^^^^^
  File "/home/runner/workspace/.pythonlibs/lib/python3.11/site-packages/sqlalchemy/orm/strategies.py", line 1141, in _emit_lazyload
    result = session.execute(
             ^^^^^^^^^^^^^^^^
  File "/home/runner/workspace/.pythonlibs/lib/python3.11/site-packages/sqlalchemy/orm/session.py", line 2365, in execute
    return self._execute_internal(
           ^^^^^^^^^^^^^^^^^^^^^^^
  File "/home/runner/workspace/.pythonlibs/lib/python3.11/site-packages/sqlalchemy/orm/session.py", line 2251, in _execute_internal
    result: Result[Any] = compile_state_cls.orm_execute_statement(
                          ^^^^^^^^^^^^^^^^^^^^^^^^^^^^^^^^^^^^^^^^
  File "/home/runner/workspace/.pythonlibs/lib/python3.11/site-packages/sqlalchemy/orm/context.py", line 305, in orm_execute_statement
    result = conn.execute(
             ^^^^^^^^^^^^^
  File "/home/runner/workspace/.pythonlibs/lib/python3.11/site-packages/sqlalchemy/engine/base.py", line 1416, in execute
    return meth(
           ^^^^^
  File "/home/runner/workspace/.pythonlibs/lib/python3.11/site-packages/sqlalchemy/sql/elements.py", line 516, in _execute_on_connection
    return connection._execute_clauseelement(
           ^^^^^^^^^^^^^^^^^^^^^^^^^^^^^^^^^^
  File "/home/runner/workspace/.pythonlibs/lib/python3.11/site-packages/sqlalchemy/engine/base.py", line 1638, in _execute_clauseelement
    ret = self._execute_context(
          ^^^^^^^^^^^^^^^^^^^^^^
  File "/home/runner/workspace/.pythonlibs/lib/python3.11/site-packages/sqlalchemy/engine/base.py", line 1843, in _execute_context
    return self._exec_single_context(
           ^^^^^^^^^^^^^^^^^^^^^^^^^^
  File "/home/runner/workspace/.pythonlibs/lib/python3.11/site-packages/sqlalchemy/engine/base.py", line 1983, in _exec_single_context
    self._handle_dbapi_exception(
  File "/home/runner/workspace/.pythonlibs/lib/python3.11/site-packages/sqlalchemy/engine/base.py", line 2355, in _handle_dbapi_exception
    raise exc_info[1].with_traceback(exc_info[2])
  File "/home/runner/workspace/.pythonlibs/lib/python3.11/site-packages/sqlalchemy/engine/base.py", line 1964, in _exec_single_context
    self.dialect.do_execute(
  File "/home/runner/workspace/.pythonlibs/lib/python3.11/site-packages/sqlalchemy/engine/default.py", line 942, in do_execute
    cursor.execute(statement, parameters)
  File "/home/runner/workspace/.pythonlibs/lib/python3.11/site-packages/sqlalchemy/dialects/postgresql/asyncpg.py", line 580, in execute
    self._adapt_connection.await_(
  File "/home/runner/workspace/.pythonlibs/lib/python3.11/site-packages/sqlalchemy/util/_concurrency_py3k.py", line 123, in await_only
    raise exc.MissingGreenlet(
sqlalchemy.exc.MissingGreenlet: greenlet_spawn has not been called; can't call await_only() here. Was IO attempted in an unexpected place? (Background on this error at: https://sqlalche.me/e/20/xd2s)
2025-03-12 11:00:53,723 INFO sqlalchemy.engine.Engine ROLLBACK
2025-03-12 11:00:53,723 - sqlalchemy.engine.Engine - INFO - ROLLBACK
2025-03-12 11:00:53,884 - app.main - WARNING - HTTP exception: greenlet_spawn has not been called; can't call await_only() here. Was IO attempted in an unexpected place? (Background on this error at: https://sqlalche.me/e/20/xd2s)
2025-03-12 11:00:53,885 - app.main - DEBUG - Created standard error detail structure: {'message': "greenlet_spawn has not been called; can't call await_only() here. Was IO attempted in an unexpected place? (Background on this error at: https://sqlalche.me/e/20/xd2s)", 'logout': False, 'details': [{'msg': "greenlet_spawn has not been called; can't call await_only() here. Was IO attempted in an unexpected place? (Background on this error at: https://sqlalche.me/e/20/xd2s)"}]}
2025-03-12 11:00:53,885 - app.api.v1.middlewares.request_logging_middleware - INFO - Request completed: GET /api/v1/organizations/13 - Status: 500 (Duration: 4.73s)
INFO:     172.31.128.45:46674 - "GET /api/v1/organizations/13 HTTP/1.1" 500 Internal Server Error