2025-03-06 19:26:45,399 - app.core.services.redis_service - DEBUG - Successfully set Redis key: user:user_qTSfFwc7HRuRaEqqYwpjiHzdq
2025-03-06 19:26:45,399 - app.core.security - DEBUG - Cached user data for fp: user_qTSfFwc7HRuRaEqqYwpjiHzdq
2025-03-06 19:26:45,400 - app.api.v1.dashboard_routes - INFO - Fetching dashboard data for user: tunaycl@outlook.com, fp: user_qTSfFwc7HRuRaEqqYwpjiHzdq
2025-03-06 19:26:45,400 - app.database.repositories.organization_repository - INFO - Fetching organizations for user_id: 1
2025-03-06 19:26:45,403 INFO sqlalchemy.engine.Engine SELECT organizations.id, organizations.name, organizations.description, organizations.created_at, organizations.updated_at 
FROM organizations JOIN user_organizations AS user_organizations_1 ON organizations.id = user_organizations_1.organization_id JOIN users ON users.id = user_organizations_1.user_id 
WHERE users.id = $1::INTEGER
2025-03-06 19:26:45,403 - sqlalchemy.engine.Engine - INFO - SELECT organizations.id, organizations.name, organizations.description, organizations.created_at, organizations.updated_at 
FROM organizations JOIN user_organizations AS user_organizations_1 ON organizations.id = user_organizations_1.organization_id JOIN users ON users.id = user_organizations_1.user_id 
WHERE users.id = $1::INTEGER
2025-03-06 19:26:45,403 INFO sqlalchemy.engine.Engine [generated in 0.00016s] (1,)
2025-03-06 19:26:45,403 - sqlalchemy.engine.Engine - INFO - [generated in 0.00016s] (1,)
2025-03-06 19:26:45,725 - app.database.repositories.organization_repository - INFO - Found 0 organizations for user 1
2025-03-06 19:26:45,725 - app.api.v1.dashboard_routes - INFO - Found 0 organizations for user
2025-03-06 19:26:45,725 - app.database.repositories.dashboard_stats_repository - INFO - Fetching stats for user_id: 1
2025-03-06 19:26:45,725 - app.database.repositories.dashboard_stats_repository - DEBUG - Cache miss, querying database...
2025-03-06 19:26:45,725 - app.database.repositories.dashboard_stats_repository - DEBUG - Querying materialized view...
2025-03-06 19:26:45,725 INFO sqlalchemy.engine.Engine 
                    SELECT * FROM mv_user_stats WHERE user_id = $1
                
2025-03-06 19:26:45,725 - sqlalchemy.engine.Engine - INFO - 
                    SELECT * FROM mv_user_stats WHERE user_id = $1
                
2025-03-06 19:26:45,725 INFO sqlalchemy.engine.Engine [generated in 0.00018s] (1,)
2025-03-06 19:26:45,725 - sqlalchemy.engine.Engine - INFO - [generated in 0.00018s] (1,)
2025-03-06 19:26:46,046 - app.database.repositories.dashboard_stats_repository - DEBUG - Materialized view query result: None
2025-03-06 19:26:46,046 - app.database.repositories.dashboard_stats_repository - INFO - No data in materialized view, updating stats...
2025-03-06 19:26:46,046 INFO sqlalchemy.engine.Engine 
                        SELECT update_user_stats($1)
                    
2025-03-06 19:26:46,046 - sqlalchemy.engine.Engine - INFO - 
                        SELECT update_user_stats($1)
                    
2025-03-06 19:26:46,046 INFO sqlalchemy.engine.Engine [generated in 0.00015s] (1,)
2025-03-06 19:26:46,046 - sqlalchemy.engine.Engine - INFO - [generated in 0.00015s] (1,)
2025-03-06 19:26:46,378 - app.database.repositories.dashboard_stats_repository - ERROR - Error updating user stats: (sqlalchemy.dialects.postgresql.asyncpg.Error) <class 'asyncpg.exceptions.ObjectNotInPrerequisiteStateError'>: ON CONFLICT does not support deferrable unique constraints/exclusion constraints as arbiters
[SQL: 
                        SELECT update_user_stats($1)
                    ]
[parameters: (1,)]
(Background on this error at: https://sqlalche.me/e/20/dbapi)
Traceback (most recent call last):
  File "/home/runner/workspace/.pythonlibs/lib/python3.11/site-packages/sqlalchemy/dialects/postgresql/asyncpg.py", line 545, in _prepare_and_execute
    self._rows = deque(await prepared_stmt.fetch(*parameters))
                       ^^^^^^^^^^^^^^^^^^^^^^^^^^^^^^^^^^^^^^
  File "/home/runner/workspace/.pythonlibs/lib/python3.11/site-packages/asyncpg/prepared_stmt.py", line 176, in fetch
    data = await self.__bind_execute(args, 0, timeout)
           ^^^^^^^^^^^^^^^^^^^^^^^^^^^^^^^^^^^^^^^^^^^
  File "/home/runner/workspace/.pythonlibs/lib/python3.11/site-packages/asyncpg/prepared_stmt.py", line 267, in __bind_execute
    data, status, _ = await self.__do_execute(
                      ^^^^^^^^^^^^^^^^^^^^^^^^
  File "/home/runner/workspace/.pythonlibs/lib/python3.11/site-packages/asyncpg/prepared_stmt.py", line 256, in __do_execute
    return await executor(protocol)
           ^^^^^^^^^^^^^^^^^^^^^^^^
  File "asyncpg/protocol/protocol.pyx", line 206, in bind_execute
asyncpg.exceptions.ObjectNotInPrerequisiteStateError: ON CONFLICT does not support deferrable unique constraints/exclusion constraints as arbiters

The above exception was the direct cause of the following exception:

Traceback (most recent call last):
  File "/home/runner/workspace/.pythonlibs/lib/python3.11/site-packages/sqlalchemy/engine/base.py", line 1964, in _exec_single_context
    self.dialect.do_execute(
  File "/home/runner/workspace/.pythonlibs/lib/python3.11/site-packages/sqlalchemy/engine/default.py", line 942, in do_execute
    cursor.execute(statement, parameters)
  File "/home/runner/workspace/.pythonlibs/lib/python3.11/site-packages/sqlalchemy/dialects/postgresql/asyncpg.py", line 580, in execute
    self._adapt_connection.await_(
  File "/home/runner/workspace/.pythonlibs/lib/python3.11/site-packages/sqlalchemy/util/_concurrency_py3k.py", line 132, in await_only
    return current.parent.switch(awaitable)  # type: ignore[no-any-return,attr-defined] # noqa: E501
           ^^^^^^^^^^^^^^^^^^^^^^^^^^^^^^^^
  File "/home/runner/workspace/.pythonlibs/lib/python3.11/site-packages/sqlalchemy/util/_concurrency_py3k.py", line 196, in greenlet_spawn
    value = await result
            ^^^^^^^^^^^^
  File "/home/runner/workspace/.pythonlibs/lib/python3.11/site-packages/sqlalchemy/dialects/postgresql/asyncpg.py", line 558, in _prepare_and_execute
    self._handle_exception(error)
  File "/home/runner/workspace/.pythonlibs/lib/python3.11/site-packages/sqlalchemy/dialects/postgresql/asyncpg.py", line 508, in _handle_exception
    self._adapt_connection._handle_exception(error)
  File "/home/runner/workspace/.pythonlibs/lib/python3.11/site-packages/sqlalchemy/dialects/postgresql/asyncpg.py", line 792, in _handle_exception
    raise translated_error from error
sqlalchemy.dialects.postgresql.asyncpg.AsyncAdapt_asyncpg_dbapi.Error: <class 'asyncpg.exceptions.ObjectNotInPrerequisiteStateError'>: ON CONFLICT does not support deferrable unique constraints/exclusion constraints as arbiters

The above exception was the direct cause of the following exception:

Traceback (most recent call last):
  File "/home/runner/workspace/app/database/repositories/dashboard_stats_repository.py", line 70, in get_user_stats
    await self.db.execute(text("""
  File "/home/runner/workspace/.pythonlibs/lib/python3.11/site-packages/sqlalchemy/ext/asyncio/session.py", line 463, in execute
    result = await greenlet_spawn(
             ^^^^^^^^^^^^^^^^^^^^^
  File "/home/runner/workspace/.pythonlibs/lib/python3.11/site-packages/sqlalchemy/util/_concurrency_py3k.py", line 201, in greenlet_spawn
    result = context.throw(*sys.exc_info())
             ^^^^^^^^^^^^^^^^^^^^^^^^^^^^^^
  File "/home/runner/workspace/.pythonlibs/lib/python3.11/site-packages/sqlalchemy/orm/session.py", line 2365, in execute
    return self._execute_internal(
           ^^^^^^^^^^^^^^^^^^^^^^^
  File "/home/runner/workspace/.pythonlibs/lib/python3.11/site-packages/sqlalchemy/orm/session.py", line 2260, in _execute_internal
    result = conn.execute(
             ^^^^^^^^^^^^^
  File "/home/runner/workspace/.pythonlibs/lib/python3.11/site-packages/sqlalchemy/engine/base.py", line 1416, in execute
    return meth(
           ^^^^^
  File "/home/runner/workspace/.pythonlibs/lib/python3.11/site-packages/sqlalchemy/sql/elements.py", line 516, in _execute_on_connection
    return connection._execute_clauseelement(
           ^^^^^^^^^^^^^^^^^^^^^^^^^^^^^^^^^^
  File "/home/runner/workspace/.pythonlibs/lib/python3.11/site-packages/sqlalchemy/engine/base.py", line 1638, in _execute_clauseelement
    ret = self._execute_context(
          ^^^^^^^^^^^^^^^^^^^^^^
  File "/home/runner/workspace/.pythonlibs/lib/python3.11/site-packages/sqlalchemy/engine/base.py", line 1843, in _execute_context
    return self._exec_single_context(
           ^^^^^^^^^^^^^^^^^^^^^^^^^^
  File "/home/runner/workspace/.pythonlibs/lib/python3.11/site-packages/sqlalchemy/engine/base.py", line 1983, in _exec_single_context
    self._handle_dbapi_exception(
  File "/home/runner/workspace/.pythonlibs/lib/python3.11/site-packages/sqlalchemy/engine/base.py", line 2352, in _handle_dbapi_exception
    raise sqlalchemy_exception.with_traceback(exc_info[2]) from e
  File "/home/runner/workspace/.pythonlibs/lib/python3.11/site-packages/sqlalchemy/engine/base.py", line 1964, in _exec_single_context
    self.dialect.do_execute(
  File "/home/runner/workspace/.pythonlibs/lib/python3.11/site-packages/sqlalchemy/engine/default.py", line 942, in do_execute
    cursor.execute(statement, parameters)
  File "/home/runner/workspace/.pythonlibs/lib/python3.11/site-packages/sqlalchemy/dialects/postgresql/asyncpg.py", line 580, in execute
    self._adapt_connection.await_(
  File "/home/runner/workspace/.pythonlibs/lib/python3.11/site-packages/sqlalchemy/util/_concurrency_py3k.py", line 132, in await_only
    return current.parent.switch(awaitable)  # type: ignore[no-any-return,attr-defined] # noqa: E501
           ^^^^^^^^^^^^^^^^^^^^^^^^^^^^^^^^
  File "/home/runner/workspace/.pythonlibs/lib/python3.11/site-packages/sqlalchemy/util/_concurrency_py3k.py", line 196, in greenlet_spawn
    value = await result
            ^^^^^^^^^^^^
  File "/home/runner/workspace/.pythonlibs/lib/python3.11/site-packages/sqlalchemy/dialects/postgresql/asyncpg.py", line 558, in _prepare_and_execute
    self._handle_exception(error)
  File "/home/runner/workspace/.pythonlibs/lib/python3.11/site-packages/sqlalchemy/dialects/postgresql/asyncpg.py", line 508, in _handle_exception
    self._adapt_connection._handle_exception(error)
  File "/home/runner/workspace/.pythonlibs/lib/python3.11/site-packages/sqlalchemy/dialects/postgresql/asyncpg.py", line 792, in _handle_exception
    raise translated_error from error
sqlalchemy.exc.DBAPIError: (sqlalchemy.dialects.postgresql.asyncpg.Error) <class 'asyncpg.exceptions.ObjectNotInPrerequisiteStateError'>: ON CONFLICT does not support deferrable unique constraints/exclusion constraints as arbiters
[SQL: 
                        SELECT update_user_stats($1)
                    ]
[parameters: (1,)]
(Background on this error at: https://sqlalche.me/e/20/dbapi)

2025-03-06 19:26:46,378 - app.api.v1.dashboard_routes - INFO - User stats retrieved: None
2025-03-06 19:26:46,378 - app.api.v1.dashboard_routes - INFO - Dashboard data retrieved successfully for user: tunaycl@outlook.com
2025-03-06 19:26:46,378 INFO sqlalchemy.engine.Engine ROLLBACK
2025-03-06 19:26:46,378 - sqlalchemy.engine.Engine - INFO - ROLLBACK
INFO:     172.31.128.20:57664 - "GET /api/v1/dashboard HTTP/1.1" 200 OK