INFO:     Application startup complete.
2025-03-05 14:19:08,997 INFO sqlalchemy.engine.Engine ROLLBACK
2025-03-05 14:19:08,997 - sqlalchemy.engine.Engine - INFO - ROLLBACK
2025-03-05 14:19:09,516 - app.main - ERROR - Error updating dashboard statistics: (sqlalchemy.dialects.postgresql.asyncpg.Error) <class 'asyncpg.exceptions.ObjectNotInPrerequisiteStateError'>: cannot refresh materialized view "public.mv_user_stats" concurrently
HINT:  Create a unique index with no WHERE clause on one or more columns of the materialized view.
[SQL: SELECT refresh_dashboard_stats_views()]
(Background on this error at: https://sqlalche.me/e/20/dbapi)
Traceback (most recent call last):
  File "/home/runner/workspace/.pythonlibs/lib/python3.11/site-packages/sqlalchemy/dialects/postgresql/asyncpg.py", line 545, in _prepare_and_execute
    self._rows = deque(await prepared_stmt.fetch(*parameters))
                       ^^^^^^^^^^^^^^^^^^^^^^^^^^^^^^^^^^^^^^
  File "/home/runner/workspace/.pythonlibs/lib/python3.11/site-packages/asyncpg/prepared_stmt.py", line 176, in fetch
    data = await self.__bind_execute(args, 0, timeout)
           ^^^^^^^^^^^^^^^^^^^^^^^^^^^^^^^^^^^^^^^^^^^
  File "/home/runner/workspace/.pythonlibs/lib/python3.11/site-packages/asyncpg/prepared_stmt.py", line 267, in __bind_execute
    data, status, _ = await self.__do_execute(
                      ^^^^^^^^^^^^^^^^^^^^^^^^
  File "/home/runner/workspace/.pythonlibs/lib/python3.11/site-packages/asyncpg/prepared_stmt.py", line 256, in __do_execute
    return await executor(protocol)
           ^^^^^^^^^^^^^^^^^^^^^^^^
  File "asyncpg/protocol/protocol.pyx", line 206, in bind_execute
asyncpg.exceptions.ObjectNotInPrerequisiteStateError: cannot refresh materialized view "public.mv_user_stats" concurrently
HINT:  Create a unique index with no WHERE clause on one or more columns of the materialized view.

The above exception was the direct cause of the following exception:

Traceback (most recent call last):
  File "/home/runner/workspace/.pythonlibs/lib/python3.11/site-packages/sqlalchemy/engine/base.py", line 1964, in _exec_single_context
    self.dialect.do_execute(
  File "/home/runner/workspace/.pythonlibs/lib/python3.11/site-packages/sqlalchemy/engine/default.py", line 942, in do_execute
    cursor.execute(statement, parameters)
  File "/home/runner/workspace/.pythonlibs/lib/python3.11/site-packages/sqlalchemy/dialects/postgresql/asyncpg.py", line 580, in execute
    self._adapt_connection.await_(
  File "/home/runner/workspace/.pythonlibs/lib/python3.11/site-packages/sqlalchemy/util/_concurrency_py3k.py", line 132, in await_only
    return current.parent.switch(awaitable)  # type: ignore[no-any-return,attr-defined] # noqa: E501
           ^^^^^^^^^^^^^^^^^^^^^^^^^^^^^^^^
  File "/home/runner/workspace/.pythonlibs/lib/python3.11/site-packages/sqlalchemy/util/_concurrency_py3k.py", line 196, in greenlet_spawn
    value = await result
            ^^^^^^^^^^^^
  File "/home/runner/workspace/.pythonlibs/lib/python3.11/site-packages/sqlalchemy/dialects/postgresql/asyncpg.py", line 558, in _prepare_and_execute
    self._handle_exception(error)
  File "/home/runner/workspace/.pythonlibs/lib/python3.11/site-packages/sqlalchemy/dialects/postgresql/asyncpg.py", line 508, in _handle_exception
    self._adapt_connection._handle_exception(error)
  File "/home/runner/workspace/.pythonlibs/lib/python3.11/site-packages/sqlalchemy/dialects/postgresql/asyncpg.py", line 792, in _handle_exception
    raise translated_error from error
sqlalchemy.dialects.postgresql.asyncpg.AsyncAdapt_asyncpg_dbapi.Error: <class 'asyncpg.exceptions.ObjectNotInPrerequisiteStateError'>: cannot refresh materialized view "public.mv_user_stats" concurrently
HINT:  Create a unique index with no WHERE clause on one or more columns of the materialized view.

The above exception was the direct cause of the following exception:

Traceback (most recent call last):
  File "/home/runner/workspace/app/main.py", line 77, in update_dashboard_stats_task
    await db.execute(text("SELECT refresh_dashboard_stats_views()"))
  File "/home/runner/workspace/.pythonlibs/lib/python3.11/site-packages/sqlalchemy/ext/asyncio/session.py", line 463, in execute
    result = await greenlet_spawn(
             ^^^^^^^^^^^^^^^^^^^^^
  File "/home/runner/workspace/.pythonlibs/lib/python3.11/site-packages/sqlalchemy/util/_concurrency_py3k.py", line 201, in greenlet_spawn
    result = context.throw(*sys.exc_info())
             ^^^^^^^^^^^^^^^^^^^^^^^^^^^^^^
  File "/home/runner/workspace/.pythonlibs/lib/python3.11/site-packages/sqlalchemy/orm/session.py", line 2365, in execute
    return self._execute_internal(
           ^^^^^^^^^^^^^^^^^^^^^^^
  File "/home/runner/workspace/.pythonlibs/lib/python3.11/site-packages/sqlalchemy/orm/session.py", line 2260, in _execute_internal
    result = conn.execute(
             ^^^^^^^^^^^^^
  File "/home/runner/workspace/.pythonlibs/lib/python3.11/site-packages/sqlalchemy/engine/base.py", line 1416, in execute
    return meth(
           ^^^^^
  File "/home/runner/workspace/.pythonlibs/lib/python3.11/site-packages/sqlalchemy/sql/elements.py", line 516, in _execute_on_connection
    return connection._execute_clauseelement(
           ^^^^^^^^^^^^^^^^^^^^^^^^^^^^^^^^^^
  File "/home/runner/workspace/.pythonlibs/lib/python3.11/site-packages/sqlalchemy/engine/base.py", line 1638, in _execute_clauseelement
    ret = self._execute_context(
          ^^^^^^^^^^^^^^^^^^^^^^
  File "/home/runner/workspace/.pythonlibs/lib/python3.11/site-packages/sqlalchemy/engine/base.py", line 1843, in _execute_context
    return self._exec_single_context(
           ^^^^^^^^^^^^^^^^^^^^^^^^^^
  File "/home/runner/workspace/.pythonlibs/lib/python3.11/site-packages/sqlalchemy/engine/base.py", line 1983, in _exec_single_context
    self._handle_dbapi_exception(
  File "/home/runner/workspace/.pythonlibs/lib/python3.11/site-packages/sqlalchemy/engine/base.py", line 2352, in _handle_dbapi_exception
    raise sqlalchemy_exception.with_traceback(exc_info[2]) from e
  File "/home/runner/workspace/.pythonlibs/lib/python3.11/site-packages/sqlalchemy/engine/base.py", line 1964, in _exec_single_context
    self.dialect.do_execute(
  File "/home/runner/workspace/.pythonlibs/lib/python3.11/site-packages/sqlalchemy/engine/default.py", line 942, in do_execute
    cursor.execute(statement, parameters)
  File "/home/runner/workspace/.pythonlibs/lib/python3.11/site-packages/sqlalchemy/dialects/postgresql/asyncpg.py", line 580, in execute
    self._adapt_connection.await_(
  File "/home/runner/workspace/.pythonlibs/lib/python3.11/site-packages/sqlalchemy/util/_concurrency_py3k.py", line 132, in await_only
    return current.parent.switch(awaitable)  # type: ignore[no-any-return,attr-defined] # noqa: E501
           ^^^^^^^^^^^^^^^^^^^^^^^^^^^^^^^^
  File "/home/runner/workspace/.pythonlibs/lib/python3.11/site-packages/sqlalchemy/util/_concurrency_py3k.py", line 196, in greenlet_spawn
    value = await result
            ^^^^^^^^^^^^
  File "/home/runner/workspace/.pythonlibs/lib/python3.11/site-packages/sqlalchemy/dialects/postgresql/asyncpg.py", line 558, in _prepare_and_execute
    self._handle_exception(error)
  File "/home/runner/workspace/.pythonlibs/lib/python3.11/site-packages/sqlalchemy/dialects/postgresql/asyncpg.py", line 508, in _handle_exception
    self._adapt_connection._handle_exception(error)
  File "/home/runner/workspace/.pythonlibs/lib/python3.11/site-packages/sqlalchemy/dialects/postgresql/asyncpg.py", line 792, in _handle_exception
    raise translated_error from error
sqlalchemy.exc.DBAPIError: (sqlalchemy.dialects.postgresql.asyncpg.Error) <class 'asyncpg.exceptions.ObjectNotInPrerequisiteStateError'>: cannot refresh materialized view "public.mv_user_stats" concurrently
HINT:  Create a unique index with no WHERE clause on one or more columns of the materialized view.
[SQL: SELECT refresh_dashboard_stats_views()]
(Background on this error at: https://sqlalche.me/e/20/dbapi)
INFO:     172.31.128.104:60502 - "GET /?initialPath=%2F&id=%3Arkn%3A HTTP/1.1" 200 OK