6,err_zo5aTTlMOXMW07I2pxIZ0BPyW,HTTP_500,500: An error occurred during document analysis,"Traceback (most recent call last):
  File ""/home/pientyai-api/app/api/v1/document_analysis_routes.py"", line 83, in analyze_document
    analysis_record = await document_analysis_service.create_analysis_record_by_fp(
                      ^^^^^^^^^^^^^^^^^^^^^^^^^^^^^^^^^^^^^^^^^^^^^^^^^^^^^^^^^^^^^
  File ""/home/pientyai-api/app/core/services/document_analysis_service.py"", line 389, in create_analysis_record_by_fp
    analysis = DocumentAnalysis(
               ^^^^^^^^^^^^^^^^^
  File ""<string>"", line 4, in __init__
  File ""/usr/local/lib/python3.11/dist-packages/sqlalchemy/orm/state.py"", line 571, in _initialize_instance
    with util.safe_reraise():
  File ""/usr/local/lib/python3.11/dist-packages/sqlalchemy/util/langhelpers.py"", line 146, in __exit__
    raise exc_value.with_traceback(exc_tb)
  File ""/usr/local/lib/python3.11/dist-packages/sqlalchemy/orm/state.py"", line 569, in _initialize_instance
    manager.original_init(*mixed[1:], **kwargs)
  File ""/usr/local/lib/python3.11/dist-packages/sqlalchemy/orm/decl_base.py"", line 2175, in _declarative_constructor
    raise TypeError(
TypeError: 'document_fp' is an invalid keyword argument for DocumentAnalysis

During handling of the above exception, another exception occurred:

Traceback (most recent call last):
  File ""/usr/local/lib/python3.11/dist-packages/starlette/_exception_handler.py"", line 42, in wrapped_app
    await app(scope, receive, sender)
  File ""/usr/local/lib/python3.11/dist-packages/starlette/routing.py"", line 73, in app
    response = await f(request)
               ^^^^^^^^^^^^^^^^
  File ""/usr/local/lib/python3.11/dist-packages/fastapi/routing.py"", line 301, in app
    raw_response = await run_endpoint_function(
                   ^^^^^^^^^^^^^^^^^^^^^^^^^^^^
  File ""/usr/local/lib/python3.11/dist-packages/fastapi/routing.py"", line 212, in run_endpoint_function
    return await dependant.call(**values)
           ^^^^^^^^^^^^^^^^^^^^^^^^^^^^^^
  File ""/home/pientyai-api/app/api/v1/document_analysis_routes.py"", line 154, in analyze_document
    raise HTTPException(
fastapi.exceptions.HTTPException: 500: An error occurred during document analysis
",document_analysis_routes.py,analyze_document,154,521f2ba1-a80a-4b93-985d-7ef0e66b0030,,127.0.0.1,http://api.pienty.ai/api/v1/document-analysis,POST,r-server55024-qjk,development,{},0,,,2025-04-17 10:38:53.071108 +00:00,
