2025-03-05 14:11:58,050 INFO sqlalchemy.engine.Engine ROLLBACK
2025-03-05 14:11:58,050 - sqlalchemy.engine.Engine - INFO - ROLLBACK
INFO:     127.0.0.1:44886 - "POST /api/v1/auth/register HTTP/1.1" 200 OK
2025-03-05 14:13:06,480 - app.core.security - DEBUG - Successfully decoded token for user: newtest@example.com
2025-03-05 14:13:06,823 - app.core.services.redis_service - DEBUG - Successfully retrieved Redis key: user:user_aQNGdhSXunm35aqP54Kzpsuns
2025-03-05 14:13:06,823 - app.core.security - INFO - Retrieved user data from Redis cache for fp: user_aQNGdhSXunm35aqP54Kzpsuns
2025-03-05 14:13:06,823 - app.api.v1.auth - DEBUG - Retrieved user from cache: newtest@example.com
2025-03-05 14:13:06,823 - app.api.v1.dashboard_routes - INFO - Fetching dashboard data for user: newtest@example.com, fp: user_aQNGdhSXunm35aqP54Kzpsuns
2025-03-05 14:13:06,823 - app.database.repositories.organization_repository - INFO - Fetching organizations for user_id: 3
2025-03-05 14:13:06,824 INFO sqlalchemy.engine.Engine BEGIN (implicit)
2025-03-05 14:13:06,824 - sqlalchemy.engine.Engine - INFO - BEGIN (implicit)
2025-03-05 14:13:06,827 INFO sqlalchemy.engine.Engine SELECT organizations.id, organizations.name, organizations.description, organizations.created_at, organizations.updated_at 
FROM organizations JOIN user_organizations AS user_organizations_1 ON organizations.id = user_organizations_1.organization_id JOIN users ON users.id = user_organizations_1.user_id 
WHERE users.id = $1::INTEGER
2025-03-05 14:13:06,827 - sqlalchemy.engine.Engine - INFO - SELECT organizations.id, organizations.name, organizations.description, organizations.created_at, organizations.updated_at 
FROM organizations JOIN user_organizations AS user_organizations_1 ON organizations.id = user_organizations_1.organization_id JOIN users ON users.id = user_organizations_1.user_id 
WHERE users.id = $1::INTEGER
2025-03-05 14:13:06,827 INFO sqlalchemy.engine.Engine [generated in 0.00017s] (3,)
2025-03-05 14:13:06,827 - sqlalchemy.engine.Engine - INFO - [generated in 0.00017s] (3,)
2025-03-05 14:13:07,360 - app.database.repositories.organization_repository - INFO - Found 0 organizations for user 3
2025-03-05 14:13:07,360 - app.api.v1.dashboard_routes - INFO - Found 0 organizations for user
2025-03-05 14:13:07,360 - app.database.repositories.dashboard_stats_repository - INFO - Fetching stats for user_id: 3
2025-03-05 14:13:07,361 INFO sqlalchemy.engine.Engine 
                SELECT * FROM mv_user_stats WHERE user_id = $1
            
2025-03-05 14:13:07,361 - sqlalchemy.engine.Engine - INFO - 
                SELECT * FROM mv_user_stats WHERE user_id = $1
            
2025-03-05 14:13:07,361 INFO sqlalchemy.engine.Engine [generated in 0.00015s] (3,)
2025-03-05 14:13:07,361 - sqlalchemy.engine.Engine - INFO - [generated in 0.00015s] (3,)
2025-03-05 14:13:07,705 INFO sqlalchemy.engine.Engine 
                    SELECT update_user_stats($1)
                
2025-03-05 14:13:07,705 - sqlalchemy.engine.Engine - INFO - 
                    SELECT update_user_stats($1)
                
2025-03-05 14:13:07,709 INFO sqlalchemy.engine.Engine [generated in 0.00374s] (3,)
2025-03-05 14:13:07,709 - sqlalchemy.engine.Engine - INFO - [generated in 0.00374s] (3,)
2025-03-05 14:13:08,055 - app.database.repositories.dashboard_stats_repository - ERROR - Error fetching user stats: (sqlalchemy.dialects.postgresql.asyncpg.ProgrammingError) <class 'asyncpg.exceptions.UndefinedFunctionError'>: function update_user_stats(unknown) does not exist
HINT:  No function matches the given name and argument types. You might need to add explicit type casts.
[SQL: 
                    SELECT update_user_stats($1)
                ]
[parameters: (3,)]
(Background on this error at: https://sqlalche.me/e/20/f405)
Traceback (most recent call last):
  File "/home/runner/workspace/.pythonlibs/lib/python3.11/site-packages/sqlalchemy/dialects/postgresql/asyncpg.py", line 521, in _prepare_and_execute
    prepared_stmt, attributes = await adapt_connection._prepare(
                                ^^^^^^^^^^^^^^^^^^^^^^^^^^^^^^^^
  File "/home/runner/workspace/.pythonlibs/lib/python3.11/site-packages/sqlalchemy/dialects/postgresql/asyncpg.py", line 768, in _prepare
    prepared_stmt = await self._connection.prepare(
                    ^^^^^^^^^^^^^^^^^^^^^^^^^^^^^^^
  File "/home/runner/workspace/.pythonlibs/lib/python3.11/site-packages/asyncpg/connection.py", line 635, in prepare
    return await self._prepare(
           ^^^^^^^^^^^^^^^^^^^^
  File "/home/runner/workspace/.pythonlibs/lib/python3.11/site-packages/asyncpg/connection.py", line 653, in _prepare
    stmt = await self._get_statement(
           ^^^^^^^^^^^^^^^^^^^^^^^^^^
  File "/home/runner/workspace/.pythonlibs/lib/python3.11/site-packages/asyncpg/connection.py", line 432, in _get_statement
    statement = await self._protocol.prepare(
                ^^^^^^^^^^^^^^^^^^^^^^^^^^^^^
  File "asyncpg/protocol/protocol.pyx", line 165, in prepare
asyncpg.exceptions.UndefinedFunctionError: function update_user_stats(unknown) does not exist
HINT:  No function matches the given name and argument types. You might need to add explicit type casts.

The above exception was the direct cause of the following exception:

Traceback (most recent call last):
  File "/home/runner/workspace/.pythonlibs/lib/python3.11/site-packages/sqlalchemy/engine/base.py", line 1964, in _exec_single_context
    self.dialect.do_execute(
  File "/home/runner/workspace/.pythonlibs/lib/python3.11/site-packages/sqlalchemy/engine/default.py", line 942, in do_execute
    cursor.execute(statement, parameters)
  File "/home/runner/workspace/.pythonlibs/lib/python3.11/site-packages/sqlalchemy/dialects/postgresql/asyncpg.py", line 580, in execute
    self._adapt_connection.await_(
  File "/home/runner/workspace/.pythonlibs/lib/python3.11/site-packages/sqlalchemy/util/_concurrency_py3k.py", line 132, in await_only
    return current.parent.switch(awaitable)  # type: ignore[no-any-return,attr-defined] # noqa: E501
           ^^^^^^^^^^^^^^^^^^^^^^^^^^^^^^^^
  File "/home/runner/workspace/.pythonlibs/lib/python3.11/site-packages/sqlalchemy/util/_concurrency_py3k.py", line 196, in greenlet_spawn
    value = await result
            ^^^^^^^^^^^^
  File "/home/runner/workspace/.pythonlibs/lib/python3.11/site-packages/sqlalchemy/dialects/postgresql/asyncpg.py", line 558, in _prepare_and_execute
    self._handle_exception(error)
  File "/home/runner/workspace/.pythonlibs/lib/python3.11/site-packages/sqlalchemy/dialects/postgresql/asyncpg.py", line 508, in _handle_exception
    self._adapt_connection._handle_exception(error)
  File "/home/runner/workspace/.pythonlibs/lib/python3.11/site-packages/sqlalchemy/dialects/postgresql/asyncpg.py", line 792, in _handle_exception
    raise translated_error from error
sqlalchemy.dialects.postgresql.asyncpg.AsyncAdapt_asyncpg_dbapi.ProgrammingError: <class 'asyncpg.exceptions.UndefinedFunctionError'>: function update_user_stats(unknown) does not exist
HINT:  No function matches the given name and argument types. You might need to add explicit type casts.

The above exception was the direct cause of the following exception:

Traceback (most recent call last):
  File "/home/runner/workspace/app/database/repositories/dashboard_stats_repository.py", line 57, in get_user_stats
    await self.db.execute(text("""
  File "/home/runner/workspace/.pythonlibs/lib/python3.11/site-packages/sqlalchemy/ext/asyncio/session.py", line 463, in execute
    result = await greenlet_spawn(
             ^^^^^^^^^^^^^^^^^^^^^
  File "/home/runner/workspace/.pythonlibs/lib/python3.11/site-packages/sqlalchemy/util/_concurrency_py3k.py", line 201, in greenlet_spawn
    result = context.throw(*sys.exc_info())
             ^^^^^^^^^^^^^^^^^^^^^^^^^^^^^^
  File "/home/runner/workspace/.pythonlibs/lib/python3.11/site-packages/sqlalchemy/orm/session.py", line 2365, in execute
    return self._execute_internal(
           ^^^^^^^^^^^^^^^^^^^^^^^
  File "/home/runner/workspace/.pythonlibs/lib/python3.11/site-packages/sqlalchemy/orm/session.py", line 2260, in _execute_internal
    result = conn.execute(
             ^^^^^^^^^^^^^
  File "/home/runner/workspace/.pythonlibs/lib/python3.11/site-packages/sqlalchemy/engine/base.py", line 1416, in execute
    return meth(
           ^^^^^
  File "/home/runner/workspace/.pythonlibs/lib/python3.11/site-packages/sqlalchemy/sql/elements.py", line 516, in _execute_on_connection
    return connection._execute_clauseelement(
           ^^^^^^^^^^^^^^^^^^^^^^^^^^^^^^^^^^
  File "/home/runner/workspace/.pythonlibs/lib/python3.11/site-packages/sqlalchemy/engine/base.py", line 1638, in _execute_clauseelement
    ret = self._execute_context(
          ^^^^^^^^^^^^^^^^^^^^^^
  File "/home/runner/workspace/.pythonlibs/lib/python3.11/site-packages/sqlalchemy/engine/base.py", line 1843, in _execute_context
    return self._exec_single_context(
           ^^^^^^^^^^^^^^^^^^^^^^^^^^
  File "/home/runner/workspace/.pythonlibs/lib/python3.11/site-packages/sqlalchemy/engine/base.py", line 1983, in _exec_single_context
    self._handle_dbapi_exception(
  File "/home/runner/workspace/.pythonlibs/lib/python3.11/site-packages/sqlalchemy/engine/base.py", line 2352, in _handle_dbapi_exception
    raise sqlalchemy_exception.with_traceback(exc_info[2]) from e
  File "/home/runner/workspace/.pythonlibs/lib/python3.11/site-packages/sqlalchemy/engine/base.py", line 1964, in _exec_single_context
    self.dialect.do_execute(
  File "/home/runner/workspace/.pythonlibs/lib/python3.11/site-packages/sqlalchemy/engine/default.py", line 942, in do_execute
    cursor.execute(statement, parameters)
  File "/home/runner/workspace/.pythonlibs/lib/python3.11/site-packages/sqlalchemy/dialects/postgresql/asyncpg.py", line 580, in execute
    self._adapt_connection.await_(
  File "/home/runner/workspace/.pythonlibs/lib/python3.11/site-packages/sqlalchemy/util/_concurrency_py3k.py", line 132, in await_only
    return current.parent.switch(awaitable)  # type: ignore[no-any-return,attr-defined] # noqa: E501
           ^^^^^^^^^^^^^^^^^^^^^^^^^^^^^^^^
  File "/home/runner/workspace/.pythonlibs/lib/python3.11/site-packages/sqlalchemy/util/_concurrency_py3k.py", line 196, in greenlet_spawn
    value = await result
            ^^^^^^^^^^^^
  File "/home/runner/workspace/.pythonlibs/lib/python3.11/site-packages/sqlalchemy/dialects/postgresql/asyncpg.py", line 558, in _prepare_and_execute
    self._handle_exception(error)
  File "/home/runner/workspace/.pythonlibs/lib/python3.11/site-packages/sqlalchemy/dialects/postgresql/asyncpg.py", line 508, in _handle_exception
    self._adapt_connection._handle_exception(error)
  File "/home/runner/workspace/.pythonlibs/lib/python3.11/site-packages/sqlalchemy/dialects/postgresql/asyncpg.py", line 792, in _handle_exception
    raise translated_error from error
sqlalchemy.exc.ProgrammingError: (sqlalchemy.dialects.postgresql.asyncpg.ProgrammingError) <class 'asyncpg.exceptions.UndefinedFunctionError'>: function update_user_stats(unknown) does not exist
HINT:  No function matches the given name and argument types. You might need to add explicit type casts.
[SQL: 
                    SELECT update_user_stats($1)
                ]
[parameters: (3,)]
(Background on this error at: https://sqlalche.me/e/20/f405)
2025-03-05 14:13:08,111 - app.api.v1.dashboard_routes - INFO - User stats retrieved: None
2025-03-05 14:13:08,111 - app.api.v1.dashboard_routes - ERROR - Error fetching dashboard data: type object 'User' has no attribute 'last_login'
Traceback (most recent call last):
  File "/home/runner/workspace/app/api/v1/dashboard_routes.py", line 129, in get_dashboard_data
    last_login=current_user.last_login
               ^^^^^^^^^^^^^^^^^^^^^^^
AttributeError: type object 'User' has no attribute 'last_login'
2025-03-05 14:13:08,112 INFO sqlalchemy.engine.Engine ROLLBACK
2025-03-05 14:13:08,112 - sqlalchemy.engine.Engine - INFO - ROLLBACK
2025-03-05 14:13:08,283 - app.main - WARNING - HTTP exception: Failed to fetch dashboard data
INFO:     127.0.0.1:40044 - "GET /api/v1/dashboard HTTP/1.1" 500 Internal Server Error